<?xml version="1.0" ?>
<mujoco model="generated_environment">
  <option timestep="0.01" integrator="RK4" cone="elliptic"/>
  <default>
    <geom density="1"/>
  </default>
  <asset>
    <texture builtin="gradient" height="3072" rgb1="0.3 0.5 0.7" rgb2="0 0 0" type="skybox" width="512"/>
    <texture builtin="checker" height="300" mark="edge" markrgb="0.8 0.8 0.8" name="groundplane" rgb1="0.2 0.3 0.4" rgb2="0.1 0.2 0.3" type="2d" width="300"/>
    <material name="groundplane" reflectance="0.2" texrepeat="5 5" texture="groundplane" texuniform="true"/>
    <material name="robot" rgba="1.0 1.0 0.0 1.0"/>
  </asset>
  <worldbody>
    <light dir="0 0 -1" directional="true" pos="0 0 1.5"/>
    <geom condim="4" friction="0.5 0.005 0.001" material="groundplane" name="floor" size="0 0 0.05" type="plane"/>
    <body name="walls">
      <geom name="wall_1" condim="4" pos="-0.06 1.9500000000000002 0.30000000000000004" rgba="0.800000011920929 0.800000011920929 0.800000011920929 1.0" size="0.06 2.0700000000000003 0.30000000000000004" type="box"/>
      <geom name="wall_2" condim="4" pos="2.7600000000000002 1.9500000000000002 0.30000000000000004" rgba="0.800000011920929 0.800000011920929 0.800000011920929 1.0" size="0.06 2.0700000000000003 0.30000000000000004" type="box"/>
      <geom name="wall_3" condim="4" pos="1.35 -0.06 0.30000000000000004" rgba="0.800000011920929 0.800000011920929 0.800000011920929 1.0" size="1.35 0.06 0.30000000000000004" type="box"/>
      <geom name="wall_4" condim="4" pos="1.35 3.9600000000000004 0.30000000000000004" rgba="0.800000011920929 0.800000011920929 0.800000011920929 1.0" size="1.35 0.06 0.30000000000000004" type="box"/>
    </body>
    <body name="robot">
      <joint name="joint_x" type="slide" pos="0 0 0" axis="1 0 0"/>
      <joint name="joint_y" type="slide" pos="0 0 0" axis="0 1 0"/>
      <geom name="robot" type="sphere" pos="1.3617868333334244 0.5301452155107035 0.15000000000000002" size="0.15000000000000002 0.15000000000000002 0.15000000000000002" mass="5.0" friction="1.0 0.005 0.0001" condim="4"/>
    </body>
    <body name="wall_5">
      <geom name="wall_5" condim="4" pos="2.039170497773397 1.376209882115591 0.30000000000000004" euler="0 0 91.6636033022931" rgba="0.800000011920929 0.800000011920929 0.800000011920929 1.0" size="0.15600000000000003 0.5700000000000001 0.30000000000000004" type="box"/>
    </body>
    <body name="obstacle_1_movable">
      <geom name="obstacle_1_movable" condim="4" pos="0.9751949411389648 1.3720733705997883 0.15000000000000002" euler="0 0 14.738735863317174" friction="0.0 0.005 0.001" rgba="1 1 0 1" size="0.15000000000000002 0.15000000000000002 0.15000000000000002" type="box" mass="0.1"/>
      <joint type="free"/>
    </body>
    <body name="obstacle_2_movable">
      <geom name="obstacle_2_movable" condim="4" pos="0.3975099330079671 1.336141421918501 0.15000000000000002" euler="0 0 314.8439989236976" friction="0.0 0.005 0.001" rgba="1 1 0 1" size="0.15000000000000002 0.15000000000000002 0.15000000000000002" type="box" mass="0.1"/>
      <joint type="free"/>
    </body>
    <site name="goal" type="sphere" size="0.30000000000000004 0.30000000000000004 0.30000000000000004" rgba="0 1 0 0.5" pos="0.40185035356879306 2.9994234025882203 0.0"/>
  </worldbody>
  <actuator>
    <motor name="actuator_x" joint="joint_x" gear="1" ctrlrange="-1 1"/>
    <motor name="actuator_y" joint="joint_y" gear="1" ctrlrange="-1 1"/>
  </actuator>
</mujoco>
