<?xml version="1.0" ?>
<mujoco model="generated_environment">
  <option timestep="0.01" integrator="RK4" cone="elliptic"/>
  <default>
    <geom density="1"/>
  </default>
  <asset>
    <texture builtin="gradient" height="3072" rgb1="0.3 0.5 0.7" rgb2="0 0 0" type="skybox" width="512"/>
    <texture builtin="checker" height="300" mark="edge" markrgb="0.8 0.8 0.8" name="groundplane" rgb1="0.2 0.3 0.4" rgb2="0.1 0.2 0.3" type="2d" width="300"/>
    <material name="groundplane" reflectance="0.2" texrepeat="5 5" texture="groundplane" texuniform="true"/>
    <material name="robot" rgba="1.0 1.0 0.0 1.0"/>
  </asset>
  <worldbody>
    <light dir="0 0 -1" directional="true" pos="0 0 1.5"/>
    <geom condim="4" friction="0.5 0.005 0.001" material="groundplane" name="floor" size="0 0 0.05" type="plane"/>
    <body name="walls">
      <geom name="wall_1" condim="4" pos="-0.01 0.325 0.05" rgba="0.800000011920929 0.800000011920929 0.800000011920929 1.0" size="0.01 0.34500000000000003 0.05" type="box"/>
      <geom name="wall_2" condim="4" pos="0.46 0.325 0.05" rgba="0.800000011920929 0.800000011920929 0.800000011920929 1.0" size="0.01 0.34500000000000003 0.05" type="box"/>
      <geom name="wall_3" condim="4" pos="0.225 -0.01 0.05" rgba="0.800000011920929 0.800000011920929 0.800000011920929 1.0" size="0.225 0.01 0.05" type="box"/>
      <geom name="wall_4" condim="4" pos="0.225 0.66 0.05" rgba="0.800000011920929 0.800000011920929 0.800000011920929 1.0" size="0.225 0.01 0.05" type="box"/>
    </body>
    <body name="robot">
      <joint name="joint_x" type="slide" pos="0 0 0" axis="1 0 0"/>
      <joint name="joint_y" type="slide" pos="0 0 0" axis="0 1 0"/>
      <geom name="robot" type="sphere" pos="0.2375546884631789 0.06491778409770108 0.025" size="0.025 0.025 0.025" mass="5.0" friction="1.0 0.005 0.0001" condim="4"/>
    </body>
    <body name="wall_5">
      <geom name="wall_5" condim="4" pos="0.29152849130834 0.22628248757325028 0.05" euler="0 0 87.24758933250007" rgba="0.800000011920929 0.800000011920929 0.800000011920929 1.0" size="0.026000000000000002 0.095 0.05" type="box"/>
    </body>
    <body name="obstacle_1_movable">
      <geom name="obstacle_1_movable" condim="4" pos="0.10497307589339336 0.23561439298184841 0.025" euler="0 0 313.1387101839716" friction="0.0 0.005 0.001" rgba="1 1 0 1" size="0.025 0.025 0.025" type="box" mass="0.1"/>
      <joint type="free"/>
    </body>
    <site name="goal" type="sphere" size="0.05 0.05 0.05" rgba="0 1 0 0.5" pos="0.06746559043292179 0.4986971968503089 0.0"/>
  </worldbody>
  <actuator>
    <motor name="actuator_x" joint="joint_x" gear="1" ctrlrange="-1 1"/>
    <motor name="actuator_y" joint="joint_y" gear="1" ctrlrange="-1 1"/>
  </actuator>
</mujoco>
